20:47:47 - executor - WARNING - _skip_updates: 358 - Updates were skipped successfully.
20:49:49 - executor - WARNING - _skip_updates: 358 - Updates were skipped successfully.
21:13:11 - executor - WARNING - _skip_updates: 358 - Updates were skipped successfully.
10:48:23 - executor - WARNING - _skip_updates: 358 - Updates were skipped successfully.
10:49:17 - executor - WARNING - start_polling: 329 - Goodbye!
10:49:17 - executor - WARNING - _skip_updates: 358 - Updates were skipped successfully.
10:49:17 - dispatcher - ERROR - start_polling: 390 - Cause exception while getting updates.
Traceback (most recent call last):
  File "/Library/Frameworks/Python.framework/Versions/3.10/lib/python3.10/site-packages/aiogram/bot/api.py", line 139, in make_request
    async with session.post(url, data=req, **kwargs) as response:
  File "/Library/Frameworks/Python.framework/Versions/3.10/lib/python3.10/site-packages/aiohttp/client.py", line 1138, in __aenter__
    self._resp = await self._coro
  File "/Library/Frameworks/Python.framework/Versions/3.10/lib/python3.10/site-packages/aiohttp/client.py", line 559, in _request
    await resp.start(conn)
  File "/Library/Frameworks/Python.framework/Versions/3.10/lib/python3.10/site-packages/aiohttp/client_reqrep.py", line 898, in start
    message, payload = await protocol.read()  # type: ignore[union-attr]
  File "/Library/Frameworks/Python.framework/Versions/3.10/lib/python3.10/site-packages/aiohttp/streams.py", line 616, in read
    await self._waiter
aiohttp.client_exceptions.ClientOSError: [Errno 1] [SSL: APPLICATION_DATA_AFTER_CLOSE_NOTIFY] application data after close notify (_ssl.c:2672)

During handling of the above exception, another exception occurred:

Traceback (most recent call last):
  File "/Library/Frameworks/Python.framework/Versions/3.10/lib/python3.10/site-packages/aiogram/dispatcher/dispatcher.py", line 381, in start_polling
    updates = await self.bot.get_updates(
  File "/Library/Frameworks/Python.framework/Versions/3.10/lib/python3.10/site-packages/aiogram/bot/bot.py", line 110, in get_updates
    result = await self.request(api.Methods.GET_UPDATES, payload)
  File "/Library/Frameworks/Python.framework/Versions/3.10/lib/python3.10/site-packages/aiogram/bot/base.py", line 231, in request
    return await api.make_request(await self.get_session(), self.server, self.__token, method, data, files,
  File "/Library/Frameworks/Python.framework/Versions/3.10/lib/python3.10/site-packages/aiogram/bot/api.py", line 142, in make_request
    raise exceptions.NetworkError(f"aiohttp client throws an error: {e.__class__.__name__}: {e}")
aiogram.utils.exceptions.NetworkError: Aiohttp client throws an error: ClientOSError: [Errno 1] [SSL: APPLICATION_DATA_AFTER_CLOSE_NOTIFY] application data after close notify (_ssl.c:2672)
10:49:22 - dispatcher - WARNING - start_polling: 405 - Polling is stopped.
10:49:27 - executor - WARNING - start_polling: 329 - Goodbye!
19:26:18 - executor - WARNING - _skip_updates: 358 - Updates were skipped successfully.
19:27:20 - executor - WARNING - start_polling: 329 - Goodbye!
19:27:21 - executor - WARNING - _skip_updates: 358 - Updates were skipped successfully.
19:27:21 - dispatcher - ERROR - start_polling: 390 - Cause exception while getting updates.
Traceback (most recent call last):
  File "/Library/Frameworks/Python.framework/Versions/3.10/lib/python3.10/site-packages/aiogram/bot/api.py", line 139, in make_request
    async with session.post(url, data=req, **kwargs) as response:
  File "/Library/Frameworks/Python.framework/Versions/3.10/lib/python3.10/site-packages/aiohttp/client.py", line 1138, in __aenter__
    self._resp = await self._coro
  File "/Library/Frameworks/Python.framework/Versions/3.10/lib/python3.10/site-packages/aiohttp/client.py", line 559, in _request
    await resp.start(conn)
  File "/Library/Frameworks/Python.framework/Versions/3.10/lib/python3.10/site-packages/aiohttp/client_reqrep.py", line 898, in start
    message, payload = await protocol.read()  # type: ignore[union-attr]
  File "/Library/Frameworks/Python.framework/Versions/3.10/lib/python3.10/site-packages/aiohttp/streams.py", line 616, in read
    await self._waiter
aiohttp.client_exceptions.ClientOSError: [Errno 1] [SSL: APPLICATION_DATA_AFTER_CLOSE_NOTIFY] application data after close notify (_ssl.c:2672)

During handling of the above exception, another exception occurred:

Traceback (most recent call last):
  File "/Library/Frameworks/Python.framework/Versions/3.10/lib/python3.10/site-packages/aiogram/dispatcher/dispatcher.py", line 381, in start_polling
    updates = await self.bot.get_updates(
  File "/Library/Frameworks/Python.framework/Versions/3.10/lib/python3.10/site-packages/aiogram/bot/bot.py", line 110, in get_updates
    result = await self.request(api.Methods.GET_UPDATES, payload)
  File "/Library/Frameworks/Python.framework/Versions/3.10/lib/python3.10/site-packages/aiogram/bot/base.py", line 231, in request
    return await api.make_request(await self.get_session(), self.server, self.__token, method, data, files,
  File "/Library/Frameworks/Python.framework/Versions/3.10/lib/python3.10/site-packages/aiogram/bot/api.py", line 142, in make_request
    raise exceptions.NetworkError(f"aiohttp client throws an error: {e.__class__.__name__}: {e}")
aiogram.utils.exceptions.NetworkError: Aiohttp client throws an error: ClientOSError: [Errno 1] [SSL: APPLICATION_DATA_AFTER_CLOSE_NOTIFY] application data after close notify (_ssl.c:2672)
19:27:21 - executor - WARNING - start_polling: 329 - Goodbye!
