21:30:12 - executor - WARNING - _skip_updates: 358 - Updates were skipped successfully.
21:32:22 - executor - WARNING - _skip_updates: 358 - Updates were skipped successfully.
21:32:42 - base_events - ERROR - default_exception_handler: 1744 - Task exception was never retrieved
future: <Task finished name='Task-9' coro=<Dispatcher._process_polling_updates() done, defined at /Library/Frameworks/Python.framework/Versions/3.10/lib/python3.10/site-packages/aiogram/dispatcher/dispatcher.py:407> exception=TypeError("Message.answer() got an unexpected keyword argument 'photo'")>
Traceback (most recent call last):
  File "/Library/Frameworks/Python.framework/Versions/3.10/lib/python3.10/site-packages/aiogram/dispatcher/dispatcher.py", line 415, in _process_polling_updates
    for responses in itertools.chain.from_iterable(await self.process_updates(updates, fast)):
  File "/Library/Frameworks/Python.framework/Versions/3.10/lib/python3.10/site-packages/aiogram/dispatcher/dispatcher.py", line 235, in process_updates
    return await asyncio.gather(*tasks)
  File "/Library/Frameworks/Python.framework/Versions/3.10/lib/python3.10/site-packages/aiogram/dispatcher/handler.py", line 116, in notify
    response = await handler_obj.handler(*args, **partial_data)
  File "/Library/Frameworks/Python.framework/Versions/3.10/lib/python3.10/site-packages/aiogram/dispatcher/dispatcher.py", line 256, in process_update
    return await self.message_handlers.notify(update.message)
  File "/Library/Frameworks/Python.framework/Versions/3.10/lib/python3.10/site-packages/aiogram/dispatcher/handler.py", line 116, in notify
    response = await handler_obj.handler(*args, **partial_data)
  File "/Users/user/Documents/TG_bot/bot/handlers.py", line 99, in send_calendar
    await message.answer(photo=open('/Users/user/Documents/TG_bot/bot/image/calendar.jpg', 'rb'))
TypeError: Message.answer() got an unexpected keyword argument 'photo'
21:33:07 - executor - WARNING - _skip_updates: 358 - Updates were skipped successfully.
21:33:08 - base_events - ERROR - default_exception_handler: 1744 - Task exception was never retrieved
future: <Task finished name='Task-9' coro=<Dispatcher._process_polling_updates() done, defined at /Library/Frameworks/Python.framework/Versions/3.10/lib/python3.10/site-packages/aiogram/dispatcher/dispatcher.py:407> exception=TypeError("Message.answer() got an unexpected keyword argument 'chat_id'")>
Traceback (most recent call last):
  File "/Library/Frameworks/Python.framework/Versions/3.10/lib/python3.10/site-packages/aiogram/dispatcher/dispatcher.py", line 415, in _process_polling_updates
    for responses in itertools.chain.from_iterable(await self.process_updates(updates, fast)):
  File "/Library/Frameworks/Python.framework/Versions/3.10/lib/python3.10/site-packages/aiogram/dispatcher/dispatcher.py", line 235, in process_updates
    return await asyncio.gather(*tasks)
  File "/Library/Frameworks/Python.framework/Versions/3.10/lib/python3.10/site-packages/aiogram/dispatcher/handler.py", line 116, in notify
    response = await handler_obj.handler(*args, **partial_data)
  File "/Library/Frameworks/Python.framework/Versions/3.10/lib/python3.10/site-packages/aiogram/dispatcher/dispatcher.py", line 256, in process_update
    return await self.message_handlers.notify(update.message)
  File "/Library/Frameworks/Python.framework/Versions/3.10/lib/python3.10/site-packages/aiogram/dispatcher/handler.py", line 116, in notify
    response = await handler_obj.handler(*args, **partial_data)
  File "/Users/user/Documents/TG_bot/bot/handlers.py", line 99, in send_calendar
    await message.answer(chat_id=message.chat.id, photo=open('/Users/user/Documents/TG_bot/bot/image/calendar.jpg', 'rb'))
TypeError: Message.answer() got an unexpected keyword argument 'chat_id'
